ERROR 2022-05-30 12:25:43,466 log 28792 29396 Internal Server Error: /social/dashboard/dpmummeui
Traceback (most recent call last):
  File "C:\Users\dougm\SimpleKnowledgeBase\env\lib\site-packages\django\core\handlers\exception.py", line 47, in inner
    response = get_response(request)
  File "C:\Users\dougm\SimpleKnowledgeBase\env\lib\site-packages\django\core\handlers\base.py", line 181, in _get_response
    response = wrapped_callback(request, *callback_args, **callback_kwargs)
  File "C:\Users\dougm\SimpleKnowledgeBase\env\lib\site-packages\django\views\generic\base.py", line 69, in view
    return self.dispatch(request, *args, **kwargs)
  File "C:\Users\dougm\SimpleKnowledgeBase\env\lib\site-packages\django\views\generic\base.py", line 101, in dispatch
    return handler(request, *args, **kwargs)
  File "C:\Users\dougm\SimpleKnowledgeBase\KnowledgeShare\social\views.py", line 19, in get
    dasboard_user = get_user_model().objects.get(username=username)
  File "C:\Users\dougm\SimpleKnowledgeBase\env\lib\site-packages\django\db\models\manager.py", line 85, in manager_method
    return getattr(self.get_queryset(), name)(*args, **kwargs)
  File "C:\Users\dougm\SimpleKnowledgeBase\env\lib\site-packages\django\db\models\query.py", line 439, in get
    raise self.model.DoesNotExist(
KnowledgeShare.users.models.User.DoesNotExist: User matching query does not exist.
ERROR 2022-05-30 12:25:43,688 basehttp 28792 29396 "GET /social/dashboard/dpmummeui HTTP/1.1" 500 99385
ERROR 2022-05-30 13:46:26,215 log 30548 29124 Internal Server Error: /users/settings
Traceback (most recent call last):
  File "C:\Users\dougm\SimpleKnowledgeBase\env\lib\site-packages\django\core\handlers\exception.py", line 47, in inner
    response = get_response(request)
  File "C:\Users\dougm\SimpleKnowledgeBase\env\lib\site-packages\django\core\handlers\base.py", line 181, in _get_response
    response = wrapped_callback(request, *callback_args, **callback_kwargs)
  File "C:\Users\dougm\SimpleKnowledgeBase\env\lib\site-packages\django\views\generic\base.py", line 69, in view
    return self.dispatch(request, *args, **kwargs)
  File "C:\Users\dougm\SimpleKnowledgeBase\env\lib\site-packages\django\contrib\auth\mixins.py", line 71, in dispatch
    return super().dispatch(request, *args, **kwargs)
  File "C:\Users\dougm\SimpleKnowledgeBase\env\lib\site-packages\django\views\generic\base.py", line 101, in dispatch
    return handler(request, *args, **kwargs)
  File "C:\Users\dougm\SimpleKnowledgeBase\KnowledgeShare\users\views.py", line 47, in post
    settings_form.save()
  File "C:\Users\dougm\SimpleKnowledgeBase\env\lib\site-packages\django\forms\models.py", line 466, in save
    self.instance.save()
  File "C:\Users\dougm\SimpleKnowledgeBase\env\lib\site-packages\django\contrib\auth\base_user.py", line 66, in save
    super().save(*args, **kwargs)
  File "C:\Users\dougm\SimpleKnowledgeBase\env\lib\site-packages\django\db\models\base.py", line 743, in save
    self.save_base(using=using, force_insert=force_insert,
  File "C:\Users\dougm\SimpleKnowledgeBase\env\lib\site-packages\django\db\models\base.py", line 780, in save_base
    updated = self._save_table(
  File "C:\Users\dougm\SimpleKnowledgeBase\env\lib\site-packages\django\db\models\base.py", line 859, in _save_table
    values = [(f, None, (getattr(self, f.attname) if raw else f.pre_save(self, False)))
  File "C:\Users\dougm\SimpleKnowledgeBase\env\lib\site-packages\django\db\models\base.py", line 859, in <listcomp>
    values = [(f, None, (getattr(self, f.attname) if raw else f.pre_save(self, False)))
  File "C:\Users\dougm\SimpleKnowledgeBase\env\lib\site-packages\django\db\models\fields\files.py", line 302, in pre_save
    file.save(file.name, file.file, save=False)
  File "C:\Users\dougm\SimpleKnowledgeBase\env\lib\site-packages\django\db\models\fields\files.py", line 89, in save
    self.name = self.storage.save(name, content, max_length=self.field.max_length)
  File "C:\Users\dougm\SimpleKnowledgeBase\env\lib\site-packages\django\core\files\storage.py", line 54, in save
    name = self._save(name, content)
  File "C:\Users\dougm\SimpleKnowledgeBase\env\lib\site-packages\storages\backends\s3boto3.py", line 459, in _save
    obj.upload_fileobj(content, ExtraArgs=params)
  File "C:\Users\dougm\SimpleKnowledgeBase\env\lib\site-packages\boto3\s3\inject.py", line 725, in object_upload_fileobj
    return self.meta.client.upload_fileobj(
  File "C:\Users\dougm\SimpleKnowledgeBase\env\lib\site-packages\boto3\s3\inject.py", line 636, in upload_fileobj
    return future.result()
  File "C:\Users\dougm\SimpleKnowledgeBase\env\lib\site-packages\s3transfer\futures.py", line 103, in result
    return self._coordinator.result()
  File "C:\Users\dougm\SimpleKnowledgeBase\env\lib\site-packages\s3transfer\futures.py", line 266, in result
    raise self._exception
  File "C:\Users\dougm\SimpleKnowledgeBase\env\lib\site-packages\s3transfer\tasks.py", line 139, in __call__
    return self._execute_main(kwargs)
  File "C:\Users\dougm\SimpleKnowledgeBase\env\lib\site-packages\s3transfer\tasks.py", line 162, in _execute_main
    return_value = self._main(**kwargs)
  File "C:\Users\dougm\SimpleKnowledgeBase\env\lib\site-packages\s3transfer\upload.py", line 758, in _main
    client.put_object(Bucket=bucket, Key=key, Body=body, **extra_args)
  File "C:\Users\dougm\SimpleKnowledgeBase\env\lib\site-packages\botocore\client.py", line 508, in _api_call
    return self._make_api_call(operation_name, kwargs)
  File "C:\Users\dougm\SimpleKnowledgeBase\env\lib\site-packages\botocore\client.py", line 911, in _make_api_call
    raise error_class(parsed_response, operation_name)
botocore.exceptions.ClientError: An error occurred (AccessControlListNotSupported) when calling the PutObject operation: The bucket does not allow ACLs
ERROR 2022-05-30 13:46:26,435 basehttp 30548 29124 "POST /users/settings HTTP/1.1" 500 23054
ERROR 2022-05-30 13:48:21,111 log 30548 14172 Internal Server Error: /users/settings
Traceback (most recent call last):
  File "C:\Users\dougm\SimpleKnowledgeBase\env\lib\site-packages\django\core\handlers\exception.py", line 47, in inner
    response = get_response(request)
  File "C:\Users\dougm\SimpleKnowledgeBase\env\lib\site-packages\django\core\handlers\base.py", line 181, in _get_response
    response = wrapped_callback(request, *callback_args, **callback_kwargs)
  File "C:\Users\dougm\SimpleKnowledgeBase\env\lib\site-packages\django\views\generic\base.py", line 69, in view
    return self.dispatch(request, *args, **kwargs)
  File "C:\Users\dougm\SimpleKnowledgeBase\env\lib\site-packages\django\contrib\auth\mixins.py", line 71, in dispatch
    return super().dispatch(request, *args, **kwargs)
  File "C:\Users\dougm\SimpleKnowledgeBase\env\lib\site-packages\django\views\generic\base.py", line 101, in dispatch
    return handler(request, *args, **kwargs)
  File "C:\Users\dougm\SimpleKnowledgeBase\KnowledgeShare\users\views.py", line 47, in post
    settings_form.save()
  File "C:\Users\dougm\SimpleKnowledgeBase\env\lib\site-packages\django\forms\models.py", line 466, in save
    self.instance.save()
  File "C:\Users\dougm\SimpleKnowledgeBase\env\lib\site-packages\django\contrib\auth\base_user.py", line 66, in save
    super().save(*args, **kwargs)
  File "C:\Users\dougm\SimpleKnowledgeBase\env\lib\site-packages\django\db\models\base.py", line 743, in save
    self.save_base(using=using, force_insert=force_insert,
  File "C:\Users\dougm\SimpleKnowledgeBase\env\lib\site-packages\django\db\models\base.py", line 780, in save_base
    updated = self._save_table(
  File "C:\Users\dougm\SimpleKnowledgeBase\env\lib\site-packages\django\db\models\base.py", line 859, in _save_table
    values = [(f, None, (getattr(self, f.attname) if raw else f.pre_save(self, False)))
  File "C:\Users\dougm\SimpleKnowledgeBase\env\lib\site-packages\django\db\models\base.py", line 859, in <listcomp>
    values = [(f, None, (getattr(self, f.attname) if raw else f.pre_save(self, False)))
  File "C:\Users\dougm\SimpleKnowledgeBase\env\lib\site-packages\django\db\models\fields\files.py", line 302, in pre_save
    file.save(file.name, file.file, save=False)
  File "C:\Users\dougm\SimpleKnowledgeBase\env\lib\site-packages\django\db\models\fields\files.py", line 89, in save
    self.name = self.storage.save(name, content, max_length=self.field.max_length)
  File "C:\Users\dougm\SimpleKnowledgeBase\env\lib\site-packages\django\core\files\storage.py", line 54, in save
    name = self._save(name, content)
  File "C:\Users\dougm\SimpleKnowledgeBase\env\lib\site-packages\storages\backends\s3boto3.py", line 459, in _save
    obj.upload_fileobj(content, ExtraArgs=params)
  File "C:\Users\dougm\SimpleKnowledgeBase\env\lib\site-packages\boto3\s3\inject.py", line 725, in object_upload_fileobj
    return self.meta.client.upload_fileobj(
  File "C:\Users\dougm\SimpleKnowledgeBase\env\lib\site-packages\boto3\s3\inject.py", line 636, in upload_fileobj
    return future.result()
  File "C:\Users\dougm\SimpleKnowledgeBase\env\lib\site-packages\s3transfer\futures.py", line 103, in result
    return self._coordinator.result()
  File "C:\Users\dougm\SimpleKnowledgeBase\env\lib\site-packages\s3transfer\futures.py", line 266, in result
    raise self._exception
  File "C:\Users\dougm\SimpleKnowledgeBase\env\lib\site-packages\s3transfer\tasks.py", line 139, in __call__
    return self._execute_main(kwargs)
  File "C:\Users\dougm\SimpleKnowledgeBase\env\lib\site-packages\s3transfer\tasks.py", line 162, in _execute_main
    return_value = self._main(**kwargs)
  File "C:\Users\dougm\SimpleKnowledgeBase\env\lib\site-packages\s3transfer\upload.py", line 758, in _main
    client.put_object(Bucket=bucket, Key=key, Body=body, **extra_args)
  File "C:\Users\dougm\SimpleKnowledgeBase\env\lib\site-packages\botocore\client.py", line 508, in _api_call
    return self._make_api_call(operation_name, kwargs)
  File "C:\Users\dougm\SimpleKnowledgeBase\env\lib\site-packages\botocore\client.py", line 911, in _make_api_call
    raise error_class(parsed_response, operation_name)
botocore.exceptions.ClientError: An error occurred (AccessControlListNotSupported) when calling the PutObject operation: The bucket does not allow ACLs
ERROR 2022-05-30 13:48:21,355 basehttp 30548 14172 "POST /users/settings HTTP/1.1" 500 22995
ERROR 2022-05-30 13:48:35,181 log 30548 19108 Internal Server Error: /users/settings
Traceback (most recent call last):
  File "C:\Users\dougm\SimpleKnowledgeBase\env\lib\site-packages\django\core\handlers\exception.py", line 47, in inner
    response = get_response(request)
  File "C:\Users\dougm\SimpleKnowledgeBase\env\lib\site-packages\django\core\handlers\base.py", line 181, in _get_response
    response = wrapped_callback(request, *callback_args, **callback_kwargs)
  File "C:\Users\dougm\SimpleKnowledgeBase\env\lib\site-packages\django\views\generic\base.py", line 69, in view
    return self.dispatch(request, *args, **kwargs)
  File "C:\Users\dougm\SimpleKnowledgeBase\env\lib\site-packages\django\contrib\auth\mixins.py", line 71, in dispatch
    return super().dispatch(request, *args, **kwargs)
  File "C:\Users\dougm\SimpleKnowledgeBase\env\lib\site-packages\django\views\generic\base.py", line 101, in dispatch
    return handler(request, *args, **kwargs)
  File "C:\Users\dougm\SimpleKnowledgeBase\KnowledgeShare\users\views.py", line 47, in post
    settings_form.save()
  File "C:\Users\dougm\SimpleKnowledgeBase\env\lib\site-packages\django\forms\models.py", line 466, in save
    self.instance.save()
  File "C:\Users\dougm\SimpleKnowledgeBase\env\lib\site-packages\django\contrib\auth\base_user.py", line 66, in save
    super().save(*args, **kwargs)
  File "C:\Users\dougm\SimpleKnowledgeBase\env\lib\site-packages\django\db\models\base.py", line 743, in save
    self.save_base(using=using, force_insert=force_insert,
  File "C:\Users\dougm\SimpleKnowledgeBase\env\lib\site-packages\django\db\models\base.py", line 780, in save_base
    updated = self._save_table(
  File "C:\Users\dougm\SimpleKnowledgeBase\env\lib\site-packages\django\db\models\base.py", line 859, in _save_table
    values = [(f, None, (getattr(self, f.attname) if raw else f.pre_save(self, False)))
  File "C:\Users\dougm\SimpleKnowledgeBase\env\lib\site-packages\django\db\models\base.py", line 859, in <listcomp>
    values = [(f, None, (getattr(self, f.attname) if raw else f.pre_save(self, False)))
  File "C:\Users\dougm\SimpleKnowledgeBase\env\lib\site-packages\django\db\models\fields\files.py", line 302, in pre_save
    file.save(file.name, file.file, save=False)
  File "C:\Users\dougm\SimpleKnowledgeBase\env\lib\site-packages\django\db\models\fields\files.py", line 89, in save
    self.name = self.storage.save(name, content, max_length=self.field.max_length)
  File "C:\Users\dougm\SimpleKnowledgeBase\env\lib\site-packages\django\core\files\storage.py", line 54, in save
    name = self._save(name, content)
  File "C:\Users\dougm\SimpleKnowledgeBase\env\lib\site-packages\storages\backends\s3boto3.py", line 459, in _save
    obj.upload_fileobj(content, ExtraArgs=params)
  File "C:\Users\dougm\SimpleKnowledgeBase\env\lib\site-packages\boto3\s3\inject.py", line 725, in object_upload_fileobj
    return self.meta.client.upload_fileobj(
  File "C:\Users\dougm\SimpleKnowledgeBase\env\lib\site-packages\boto3\s3\inject.py", line 636, in upload_fileobj
    return future.result()
  File "C:\Users\dougm\SimpleKnowledgeBase\env\lib\site-packages\s3transfer\futures.py", line 103, in result
    return self._coordinator.result()
  File "C:\Users\dougm\SimpleKnowledgeBase\env\lib\site-packages\s3transfer\futures.py", line 266, in result
    raise self._exception
  File "C:\Users\dougm\SimpleKnowledgeBase\env\lib\site-packages\s3transfer\tasks.py", line 139, in __call__
    return self._execute_main(kwargs)
  File "C:\Users\dougm\SimpleKnowledgeBase\env\lib\site-packages\s3transfer\tasks.py", line 162, in _execute_main
    return_value = self._main(**kwargs)
  File "C:\Users\dougm\SimpleKnowledgeBase\env\lib\site-packages\s3transfer\upload.py", line 758, in _main
    client.put_object(Bucket=bucket, Key=key, Body=body, **extra_args)
  File "C:\Users\dougm\SimpleKnowledgeBase\env\lib\site-packages\botocore\client.py", line 508, in _api_call
    return self._make_api_call(operation_name, kwargs)
  File "C:\Users\dougm\SimpleKnowledgeBase\env\lib\site-packages\botocore\client.py", line 911, in _make_api_call
    raise error_class(parsed_response, operation_name)
botocore.exceptions.ClientError: An error occurred (AccessControlListNotSupported) when calling the PutObject operation: The bucket does not allow ACLs
ERROR 2022-05-30 13:48:35,408 basehttp 30548 19108 "POST /users/settings HTTP/1.1" 500 22999
ERROR 2022-05-30 13:48:50,282 log 30548 15924 Internal Server Error: /users/settings
Traceback (most recent call last):
  File "C:\Users\dougm\SimpleKnowledgeBase\env\lib\site-packages\django\core\handlers\exception.py", line 47, in inner
    response = get_response(request)
  File "C:\Users\dougm\SimpleKnowledgeBase\env\lib\site-packages\django\core\handlers\base.py", line 181, in _get_response
    response = wrapped_callback(request, *callback_args, **callback_kwargs)
  File "C:\Users\dougm\SimpleKnowledgeBase\env\lib\site-packages\django\views\generic\base.py", line 69, in view
    return self.dispatch(request, *args, **kwargs)
  File "C:\Users\dougm\SimpleKnowledgeBase\env\lib\site-packages\django\contrib\auth\mixins.py", line 71, in dispatch
    return super().dispatch(request, *args, **kwargs)
  File "C:\Users\dougm\SimpleKnowledgeBase\env\lib\site-packages\django\views\generic\base.py", line 101, in dispatch
    return handler(request, *args, **kwargs)
  File "C:\Users\dougm\SimpleKnowledgeBase\KnowledgeShare\users\views.py", line 47, in post
    settings_form.save()
  File "C:\Users\dougm\SimpleKnowledgeBase\env\lib\site-packages\django\forms\models.py", line 466, in save
    self.instance.save()
  File "C:\Users\dougm\SimpleKnowledgeBase\env\lib\site-packages\django\contrib\auth\base_user.py", line 66, in save
    super().save(*args, **kwargs)
  File "C:\Users\dougm\SimpleKnowledgeBase\env\lib\site-packages\django\db\models\base.py", line 743, in save
    self.save_base(using=using, force_insert=force_insert,
  File "C:\Users\dougm\SimpleKnowledgeBase\env\lib\site-packages\django\db\models\base.py", line 780, in save_base
    updated = self._save_table(
  File "C:\Users\dougm\SimpleKnowledgeBase\env\lib\site-packages\django\db\models\base.py", line 859, in _save_table
    values = [(f, None, (getattr(self, f.attname) if raw else f.pre_save(self, False)))
  File "C:\Users\dougm\SimpleKnowledgeBase\env\lib\site-packages\django\db\models\base.py", line 859, in <listcomp>
    values = [(f, None, (getattr(self, f.attname) if raw else f.pre_save(self, False)))
  File "C:\Users\dougm\SimpleKnowledgeBase\env\lib\site-packages\django\db\models\fields\files.py", line 302, in pre_save
    file.save(file.name, file.file, save=False)
  File "C:\Users\dougm\SimpleKnowledgeBase\env\lib\site-packages\django\db\models\fields\files.py", line 89, in save
    self.name = self.storage.save(name, content, max_length=self.field.max_length)
  File "C:\Users\dougm\SimpleKnowledgeBase\env\lib\site-packages\django\core\files\storage.py", line 54, in save
    name = self._save(name, content)
  File "C:\Users\dougm\SimpleKnowledgeBase\env\lib\site-packages\storages\backends\s3boto3.py", line 459, in _save
    obj.upload_fileobj(content, ExtraArgs=params)
  File "C:\Users\dougm\SimpleKnowledgeBase\env\lib\site-packages\boto3\s3\inject.py", line 725, in object_upload_fileobj
    return self.meta.client.upload_fileobj(
  File "C:\Users\dougm\SimpleKnowledgeBase\env\lib\site-packages\boto3\s3\inject.py", line 636, in upload_fileobj
    return future.result()
  File "C:\Users\dougm\SimpleKnowledgeBase\env\lib\site-packages\s3transfer\futures.py", line 103, in result
    return self._coordinator.result()
  File "C:\Users\dougm\SimpleKnowledgeBase\env\lib\site-packages\s3transfer\futures.py", line 266, in result
    raise self._exception
  File "C:\Users\dougm\SimpleKnowledgeBase\env\lib\site-packages\s3transfer\tasks.py", line 139, in __call__
    return self._execute_main(kwargs)
  File "C:\Users\dougm\SimpleKnowledgeBase\env\lib\site-packages\s3transfer\tasks.py", line 162, in _execute_main
    return_value = self._main(**kwargs)
  File "C:\Users\dougm\SimpleKnowledgeBase\env\lib\site-packages\s3transfer\upload.py", line 758, in _main
    client.put_object(Bucket=bucket, Key=key, Body=body, **extra_args)
  File "C:\Users\dougm\SimpleKnowledgeBase\env\lib\site-packages\botocore\client.py", line 508, in _api_call
    return self._make_api_call(operation_name, kwargs)
  File "C:\Users\dougm\SimpleKnowledgeBase\env\lib\site-packages\botocore\client.py", line 911, in _make_api_call
    raise error_class(parsed_response, operation_name)
botocore.exceptions.ClientError: An error occurred (AccessControlListNotSupported) when calling the PutObject operation: The bucket does not allow ACLs
ERROR 2022-05-30 13:48:50,508 basehttp 30548 15924 "POST /users/settings HTTP/1.1" 500 22944
ERROR 2022-05-30 15:11:41,742 basehttp 27804 11056 You're accessing the development server over HTTPS, but it only supports HTTP.

ERROR 2022-05-30 15:11:43,834 basehttp 27804 29708 You're accessing the development server over HTTPS, but it only supports HTTP.

ERROR 2022-05-30 15:11:53,569 basehttp 27804 23976 You're accessing the development server over HTTPS, but it only supports HTTP.

ERROR 2022-05-30 15:11:53,570 basehttp 27804 7188 You're accessing the development server over HTTPS, but it only supports HTTP.

ERROR 2022-05-30 15:12:26,792 basehttp 10572 11380 You're accessing the development server over HTTPS, but it only supports HTTP.

ERROR 2022-05-30 15:12:27,545 basehttp 10572 11240 You're accessing the development server over HTTPS, but it only supports HTTP.

ERROR 2022-05-30 15:12:37,530 basehttp 2912 10196 You're accessing the development server over HTTPS, but it only supports HTTP.

ERROR 2022-05-30 15:12:58,503 basehttp 2912 21112 You're accessing the development server over HTTPS, but it only supports HTTP.

ERROR 2022-05-30 15:13:15,225 basehttp 2912 13316 You're accessing the development server over HTTPS, but it only supports HTTP.

ERROR 2022-05-30 15:13:15,909 basehttp 2912 29096 You're accessing the development server over HTTPS, but it only supports HTTP.

ERROR 2022-05-30 15:13:19,127 basehttp 2912 13976 You're accessing the development server over HTTPS, but it only supports HTTP.

